<?xml version="1.0" encoding="UTF-8"?>
<testng-results skipped="0" failed="2" ignored="0" total="3" passed="1">
  <reporter-output>
  </reporter-output>
  <suite name="Suite" duration-ms="80" started-at="2018-07-10T06:11:36Z" finished-at="2018-07-10T06:11:36Z">
    <groups>
    </groups>
    <test name="Test" duration-ms="80" started-at="2018-07-10T06:11:36Z" finished-at="2018-07-10T06:11:36Z">
      <class name="Jen.JenkinsBuild.AppTest">
        <test-method status="PASS" signature="verifyConditionOne()[pri:1, instance:Jen.JenkinsBuild.AppTest@35bbe5e8]" name="verifyConditionOne" duration-ms="19" started-at="2018-07-10T06:11:36Z" finished-at="2018-07-10T06:11:36Z">
          <reporter-output>
          </reporter-output>
        </test-method> <!-- verifyConditionOne -->
        <test-method status="FAIL" signature="verifyConditionTwo()[pri:2, instance:Jen.JenkinsBuild.AppTest@35bbe5e8]" name="verifyConditionTwo" duration-ms="1" started-at="2018-07-10T06:11:36Z" finished-at="2018-07-10T06:11:36Z">
          <exception class="java.lang.AssertionError">
            <message>
              <![CDATA[expected [false] but found [true]]]>
            </message>
            <full-stacktrace>
              <![CDATA[java.lang.AssertionError: expected [false] but found [true]
at org.testng.Assert.fail(Assert.java:96)
at org.testng.Assert.failNotEquals(Assert.java:776)
at org.testng.Assert.assertEqualsImpl(Assert.java:137)
at org.testng.Assert.assertEquals(Assert.java:118)
at org.testng.Assert.assertEquals(Assert.java:568)
at org.testng.Assert.assertEquals(Assert.java:578)
at Jen.JenkinsBuild.AppTest.verifyConditionTwo(AppTest.java:22)
at sun.reflect.NativeMethodAccessorImpl.invoke0(Native Method)
at sun.reflect.NativeMethodAccessorImpl.invoke(NativeMethodAccessorImpl.java:62)
at sun.reflect.DelegatingMethodAccessorImpl.invoke(DelegatingMethodAccessorImpl.java:43)
at java.lang.reflect.Method.invoke(Method.java:498)
at org.testng.internal.MethodInvocationHelper.invokeMethod(MethodInvocationHelper.java:124)
at org.testng.internal.Invoker.invokeMethod(Invoker.java:583)
at org.testng.internal.Invoker.invokeTestMethod(Invoker.java:719)
at org.testng.internal.Invoker.invokeTestMethods(Invoker.java:989)
at org.testng.internal.TestMethodWorker.invokeTestMethods(TestMethodWorker.java:125)
at org.testng.internal.TestMethodWorker.run(TestMethodWorker.java:109)
at org.testng.TestRunner.privateRun(TestRunner.java:648)
at org.testng.TestRunner.run(TestRunner.java:505)
at org.testng.SuiteRunner.runTest(SuiteRunner.java:455)
at org.testng.SuiteRunner.runSequentially(SuiteRunner.java:450)
at org.testng.SuiteRunner.privateRun(SuiteRunner.java:415)
at org.testng.SuiteRunner.run(SuiteRunner.java:364)
at org.testng.SuiteRunnerWorker.runSuite(SuiteRunnerWorker.java:52)
at org.testng.SuiteRunnerWorker.run(SuiteRunnerWorker.java:84)
at org.testng.TestNG.runSuitesSequentially(TestNG.java:1208)
at org.testng.TestNG.runSuitesLocally(TestNG.java:1137)
at org.testng.TestNG.runSuites(TestNG.java:1049)
at org.testng.TestNG.run(TestNG.java:1017)
at org.apache.maven.surefire.testng.TestNGExecutor.run(TestNGExecutor.java:281)
at org.apache.maven.surefire.testng.TestNGXmlTestSuite.execute(TestNGXmlTestSuite.java:75)
at org.apache.maven.surefire.testng.TestNGProvider.invoke(TestNGProvider.java:121)
at org.apache.maven.surefire.booter.ForkedBooter.invokeProviderInSameClassLoader(ForkedBooter.java:290)
at org.apache.maven.surefire.booter.ForkedBooter.runSuitesInProcess(ForkedBooter.java:242)
at org.apache.maven.surefire.booter.ForkedBooter.main(ForkedBooter.java:121)
]]>
            </full-stacktrace>
          </exception> <!-- java.lang.AssertionError -->
          <reporter-output>
          </reporter-output>
        </test-method> <!-- verifyConditionTwo -->
        <test-method status="FAIL" signature="verifyConditionThree()[pri:3, instance:Jen.JenkinsBuild.AppTest@35bbe5e8]" name="verifyConditionThree" duration-ms="0" started-at="2018-07-10T06:11:36Z" finished-at="2018-07-10T06:11:36Z">
          <exception class="java.lang.AssertionError">
            <message>
              <![CDATA[expected [true] but found [false]]]>
            </message>
            <full-stacktrace>
              <![CDATA[java.lang.AssertionError: expected [true] but found [false]
at org.testng.Assert.fail(Assert.java:96)
at org.testng.Assert.failNotEquals(Assert.java:776)
at org.testng.Assert.assertTrue(Assert.java:44)
at org.testng.Assert.assertTrue(Assert.java:54)
at Jen.JenkinsBuild.AppTest.verifyConditionThree(AppTest.java:29)
at sun.reflect.NativeMethodAccessorImpl.invoke0(Native Method)
at sun.reflect.NativeMethodAccessorImpl.invoke(NativeMethodAccessorImpl.java:62)
at sun.reflect.DelegatingMethodAccessorImpl.invoke(DelegatingMethodAccessorImpl.java:43)
at java.lang.reflect.Method.invoke(Method.java:498)
at org.testng.internal.MethodInvocationHelper.invokeMethod(MethodInvocationHelper.java:124)
at org.testng.internal.Invoker.invokeMethod(Invoker.java:583)
at org.testng.internal.Invoker.invokeTestMethod(Invoker.java:719)
at org.testng.internal.Invoker.invokeTestMethods(Invoker.java:989)
at org.testng.internal.TestMethodWorker.invokeTestMethods(TestMethodWorker.java:125)
at org.testng.internal.TestMethodWorker.run(TestMethodWorker.java:109)
at org.testng.TestRunner.privateRun(TestRunner.java:648)
at org.testng.TestRunner.run(TestRunner.java:505)
at org.testng.SuiteRunner.runTest(SuiteRunner.java:455)
at org.testng.SuiteRunner.runSequentially(SuiteRunner.java:450)
at org.testng.SuiteRunner.privateRun(SuiteRunner.java:415)
at org.testng.SuiteRunner.run(SuiteRunner.java:364)
at org.testng.SuiteRunnerWorker.runSuite(SuiteRunnerWorker.java:52)
at org.testng.SuiteRunnerWorker.run(SuiteRunnerWorker.java:84)
at org.testng.TestNG.runSuitesSequentially(TestNG.java:1208)
at org.testng.TestNG.runSuitesLocally(TestNG.java:1137)
at org.testng.TestNG.runSuites(TestNG.java:1049)
at org.testng.TestNG.run(TestNG.java:1017)
at org.apache.maven.surefire.testng.TestNGExecutor.run(TestNGExecutor.java:281)
at org.apache.maven.surefire.testng.TestNGXmlTestSuite.execute(TestNGXmlTestSuite.java:75)
at org.apache.maven.surefire.testng.TestNGProvider.invoke(TestNGProvider.java:121)
at org.apache.maven.surefire.booter.ForkedBooter.invokeProviderInSameClassLoader(ForkedBooter.java:290)
at org.apache.maven.surefire.booter.ForkedBooter.runSuitesInProcess(ForkedBooter.java:242)
at org.apache.maven.surefire.booter.ForkedBooter.main(ForkedBooter.java:121)
]]>
            </full-stacktrace>
          </exception> <!-- java.lang.AssertionError -->
          <reporter-output>
          </reporter-output>
        </test-method> <!-- verifyConditionThree -->
      </class> <!-- Jen.JenkinsBuild.AppTest -->
    </test> <!-- Test -->
  </suite> <!-- Suite -->
</testng-results>
